Workbook

Sheet Summary
A1: Inventory Summary Dashboard
A3: Category | B3: Line Items | C3: Total Quantity | D3: Notes
A4: Extrusions | B4: =COUNTA(Extrusion_Totals!A:A)-1 -> 111 | C4: =SUM(Extrusion_Totals!D:D) -> 29967
A5: ACM Sheets | B5: =COUNTA(ACM_Inventory!A:A)-1 -> 188 | C5: =SUM(ACM_Inventory!H:H) -> 3733
A6: Panels (SP/Trespa) | B6: =COUNTA(SPL_inventory!A:A)-1 -> 157 | C6: =SUM(SPL_inventory!H:H) -> 3468
A7: Rivets | B7: =COUNTA(Rivet_Inventory!A:A)-1 -> 85 | C7: =SUM(Rivet_Inventory!D:D) -> 631250
A8: Misc | B8: =COUNTA(Misc_Inventory!A:A)-1 -> 36 | C8: =SUM(Misc_Inventory!E:E) -> 58067.5
A10: Filtered Views
A11: DRY/PER Black & Silver | B11: =COUNTA(DRY_PER_Black_Silver!A:A)-2 -> 146 | C11: =SUM(DRY_PER_Black_Silver!E:E) -> 27672

Sheet Parts
A1: Part_ID | B1: Part_Name | C1: Color | D1: Category
A2: RDTSH-BLACK | B2: RDTSH | C2: BLACK | D2: DRY
A3: RDTSH-SILVER | B3: RDTSH | C3: SILVER | D3: DRY
A4: RDTSH-MILL | B4: RDTSH | C4: MILL | D4: DRY
A5: RDTSH-CUSTOM | B5: RDTSH | C5: CUSTOM | D5: DRY
A6: RDL-BLACK | B6: RDL | C6: BLACK | D6: DRY
A7: RDL-SILVER | B7: RDL | C7: SILVER | D7: DRY
A8: RDL-MILL | B8: RDL | C8: MILL | D8: DRY
A9: RDL-CUSTOM | B9: RDL | C9: CUSTOM | D9: DRY
A10: RDR-BLACK | B10: RDR | C10: BLACK | D10: DRY
A11: RDR-SILVER | B11: RDR | C11: SILVER | D11: DRY
A12: RDR-MILL | B12: RDR | C12: MILL | D12: DRY
... A340: SPLJ | B340: SPLJ | C340: Black | D340: Other
A341: SPLCLP8 | B341: SPLCLP8 | D341: Other
A342: SPLCLP12 | B342: SPLCLP12 | D342: Other
A343: SPECRAIL | B343: SPECRAIL | D343: Other
A344: SPFISC8 | B344: SPFISC8 | D344: Other
A345: SPFISC12 | B345: SPFISC12 | D345: Other
A346: SPLWHAT | B346: SPLWHAT | D346: Other
A347: PLTH | B347: PLTH | D347: Other
A348: PLOB | B348: PLOB | D348: Other
A349: PLL | B349: PLL | D349: Other
A350: PLR | B350: PLR | D350: Other
A351: PLTF | B351: PLTF | D351: Other
A352: PLTPH | B352: PLTPH | D352: Other
... A419: TUBE | B419: TUBE | D419: Other

Sheet Locations
A1: Location_ID | B1: Type | C1: Zone
A2: Rack 5 | B2: Rack | C2: Yard
A3: Rack 6 | B3: Rack | C3: Yard
A4: Rack 7 | B4: Rack | C4: Yard
A5: Rack 8 | B5: Rack | C5: Yard
A6: Rack 9 | B6: Rack | C6: Yard
A7: Rack 10 | B7: Rack | C7: Yard
A8: Rack 11 | B8: Rack | C8: Yard
A9: Rack 12 | B9: Rack | C9: Yard
A10: Rack 13 | B10: Rack | C10: Yard
A11: Rack 14 | B11: Rack | C11: Yard
A12: Rack 15 | B12: Rack | C12: Yard
... A52: Rivet Room | B52: Room | C52: Shop

Sheet Extrusion_Inventory
A1: Part_ID | B1: Part_Name | C1: Color | D1: Location_ID | E1: Quantity | F1: Each Cost | G1: Total
A2: RDTSH-BLACK | B2: RDTSH | C2: BLACK | D2: Rack 23 | E2: 40 | G2: =F2*E2 -> 0
A3: RDTSH-BLACK | B3: RDTSH | C3: BLACK | D3: Rack 24 | E3: 26 | G3: =F3*E3 -> 0
A4: RDTSH-SILVER | B4: RDTSH | C4: SILVER | D4: Rack 12 | E4: 88 | G4: =F4*E4 -> 0
A5: RDTSH-SILVER | B5: RDTSH | C5: SILVER | D5: Rack 15 | E5: 35 | G5: =F5*E5 -> 0
A6: RDTSH-SILVER | B6: RDTSH | C6: SILVER | D6: Ground | E6: 13 | G6: =F6*E6 -> 0
A7: RDL-BLACK | B7: RDL | C7: BLACK | D7: Rack 7 | E7: 54 | G7: =F7*E7 -> 0
A8: RDL-BLACK | B8: RDL | C8: BLACK | D8: Rack 13 | E8: 7 | G8: =F8*E8 -> 0
A9: RDL-BLACK | B9: RDL | C9: BLACK | D9: Rack 20 | E9: 288 | G9: =F9*E9 -> 0
A10: RDL-BLACK | B10: RDL | C10: BLACK | D10: Rack 23 | E10: 316 | G10: =F10*E10 -> 0
A11: RDL-BLACK | B11: RDL | C11: BLACK | D11: Rack 25 | E11: 80 | G11: =F11*E11 -> 0
A12: RDL-BLACK | B12: RDL | C12: BLACK | D12: Rack 22 | E12: 19 | G12: =F12*E12 -> 0
A13: RDL-BLACK | B13: RDL | C13: BLACK | D13: Ground | E13: 72 | G13: =F13*E13 -> 0
... A180: PERJF-BLACK | B180: PERJF | C180: BLACK | D180: Rack 27 | E180: 128 | G180: =F180*E180 -> 0
A181: SRSC4 | B181: SRSC4 | C181: Mill | D181: Rack 10 | E181: 1114 | F181: 21.91 | G181: =F181*E181 -> 24407.74
A182: SRSC4 | B182: SRSC4 | C182: Mill | D182: Ground | E182: 11 | F182: 21.91 | G182: =F182*E182 -> 241.01
A183: SRSTLC | B183: SRSTLC | C183: Cyan | D183: Rack 13 | E183: 46 | G183: =F183*E183 -> 0
A184: SRSJTC | B184: SRSJTC | C184: Black | D184: Rack 20 | E184: 44 | G184: =F184*E184 -> 0
A185: SRSJTC | B185: SRSJTC | C185: Black | D185: Rack 24 | E185: 268 | G185: =F185*E185 -> 0
A186: SRSJTC | B186: SRSJTC | C186: Black | D186: Lot | E186: 18 | G186: =F186*E186 -> 0
A187: SRSZ | B187: SRSZ | C187: White | D187: Rack 13 | E187: 146 | G187: =F187*E187 -> 0
A188: SRSJWC | B188: SRSJWC | C188: Orange | D188: Rack 20 | E188: 26 | G188: =F188*E188 -> 0
A189: SRSJTT | B189: SRSJTT | C189: Tan | D189: Rack 18 | E189: 27 | G189: =F189*E189 -> 0
A190: SRSCJX | B190: SRSCJX | C190: Black | D190: Rack 7 | E190: 91 | G190: =F190*E190 -> 0
A191: SRSFEC | B191: SRSFEC | C191: Hunter Green | D191: Shipping | E191: 145 | G191: =F191*E191 -> 0
A192: SRSTLC | B192: SRSTLC | C192: Cyan | D192: Lot | E192: 250 | G192: =F192*E192 -> 0
A193: SRSBLC | B193: SRSBLC | C193: Pink | D193: Shipping | E193: 176 | G193: =F193*E193 -> 0
A194: SRSDLV | B194: SRSDLV | C194: Adobe Brown | D194: Rack 18 | E194: 17 | G194: =F194*E194 -> 0
... A198: SRSJSC | B198: SRSJSC | C198: Yellow | D198: Shipping | E198: 142 | G198: =F198*E198 -> 0
A199: RRWR | B199: RRWR | C199: Mill | D199: Rack 19 | E199: 128 | F199: 31.02 | G199: =F199*E199 -> 3970.56
A200: RRWB | B200: RRWB | C200: Mill | D200: Rack 10 | E200: 33 | F200: 17.11 | G200: =F200*E200 -> 564.63
A201: RRWB | B201: RRWB | C201: Mill | D201: Rack 11 | E201: 43 | F201: 17.11 | G201: =F201*E201 -> 735.73
A202: RRWB | B202: RRWB | C202: Mill | D202: Rack 12 | E202: 81 | F202: 17.11 | G202: =F202*E202 -> 1385.91
A203: RRWB | B203: RRWB | C203: Mill | D203: Ground | E203: 42 | F203: 17.11 | G203: =F203*E203 -> 718.62
A204: RRWZ | B204: RRWZ | C204: Mill | D204: Rack 12 | E204: 9 | F204: 18.46 | G204: =F204*E204 -> 166.14
A205: RRWLD | B205: RRWLD | C205: Mill | D205: Rack 10 | E205: 12 | F205: 28.26 | G205: =F205*E205 -> 339.12
A206: RRWLD | B206: RRWLD | C206: Mill | D206: Rack 12 | E206: 54 | F206: 28.26 | G206: =F206*E206 -> 1526.04
A207: RRWLD | B207: RRWLD | C207: Mill | D207: Rack 14 | E207: 212 | F207: 28.26 | G207: =F207*E207 -> 5991.12
A208: RRWLD | B208: RRWLD | C208: Mill | D208: Receiving | E208: 20 | F208: 28.26 | G208: =F208*E208 -> 565.2
A209: RRWRD | B209: RRWRD | C209: Mill | D209: Rack 10 | E209: 83 | F209: 29.99 | G209: =F209*E209 -> 2489.17
...

Sheet Extrusion_Totals
A1: Part_ID | B1: Part_Name | C1: Color | D1: Total_Quantity | E1: Location_Count
A2: BVROB | B2: BVROB | D2: 130 | E2: 3
A3: BVRR | B3: BVRR | D3: 17 | E3: 1
A4: FINB | B4: FINB | D4: 156 | E4: 2
A5: FINCJ | B5: FINCJ | D5: 84 | E5: 1
A6: FTM-ACM | B6: FTM-ACM | D6: 78 | E6: 1
A7: J-SILVER | B7: J | C7: SILVER | D7: 48 | E7: 1
A8: PARTITION | B8: PARTITION | C8: Mill | D8: 31 | E8: 1
A9: PERB-BLACK | B9: PERB | C9: BLACK | D9: 146 | E9: 3
A10: PERCJ-SILVER | B10: PERCJ | C10: SILVER | D10: 70 | E10: 2
A11: PERCJF-BLACK | B11: PERCJF | C11: BLACK | D11: 315 | E11: 3
A12: PERHA-BLACK | B12: PERHA | C12: BLACK | D12: 197 | E12: 4
A13: PERHF2-BLACK | B13: PERHF2 | C13: BLACK | D13: 150 | E13: 2
A14: PERICA-BLACK | B14: PERICA | C14: BLACK | D14: 26 | E14: 1
A15: PERICA-SILVER | B15: PERICA | C15: SILVER | D15: 54 | E15: 2
A16: PERJ-BLACK | B16: PERJ | C16: BLACK | D16: 9 | E16: 1
A17: PERJE-BLACK | B17: PERJE | C17: BLACK | D17: 62 | E17: 2
A18: PERJF-BLACK | B18: PERJF | C18: BLACK | D18: 128 | E18: 1
... A112: ZEE | B112: ZEE | C112: Black | D112: 306 | E112: 4

Sheet DRY_PER_Black_Silver
A1: Part_ID | B1: Part_Name | C1: Color | D1: Category | E1: Total_Quantity
A2: J-BLACK | B2: J | C2: BLACK | D2: DRY | E2: 0
A3: J-SILVER | B3: J | C3: SILVER | D3: DRY | E3: 48
A4: RDA-BLACK | B4: RDA | C4: BLACK | D4: DRY | E4: 0
A5: RDA-SILVER | B5: RDA | C5: SILVER | D5: DRY | E5: 0
A6: RDBB-BLACK | B6: RDBB | C6: BLACK | D6: DRY | E6: 72
A7: RDBB-SILVER | B7: RDBB | C7: SILVER | D7: DRY | E7: 0
A8: RDBP-BLACK | B8: RDBP | C8: BLACK | D8: DRY | E8: 0
A9: RDBP-SILVER | B9: RDBP | C9: SILVER | D9: DRY | E9: 0
A10: RDCJ-BLACK | B10: RDCJ | C10: BLACK | D10: DRY | E10: 656
A11: RDCJ-SILVER | B11: RDCJ | C11: SILVER | D11: DRY | E11: 102
A12: RDCJC-BLACK | B12: RDCJC | C12: BLACK | D12: DRY | E12: 0
A13: RDCJC-SILVER | B13: RDCJC | C13: SILVER | D13: DRY | E13: 0
... A147: PERZ-SILVER | B147: PERZ | C147: SILVER | D147: PER | E147: 45
A149: TOTALS | E149: =SUM(E2:E147) -> 13836

Sheet ACM_Inventory
A1: Location_ID | B1: Job_Number | C1: Pallet | D1: Size_W | E1: Size_L | F1: Brand | G1: Color | H1: Quantity
A2: Row 53 | B2: 22049 | C2: 4 | D2: 62 | E2: 196 | F2: Alpolic | G2: Anodic Satin | H2: 15
A3: Row 53 | B3: 23013 | C3: 42 | D3: 62 | E3: 196 | F3: Reyobond | G3: Scarlett Red | H3: 5
A4: Row 53 | B4: 23023 | C4: 10 | D4: 60 | E4: 196 | F4: Alpolic | G4: Sunstorm Copper | H4: 29
A5: Row 53 | B5: 23023 | C5: 9 | D5: 60 | E5: 196 | F5: Alpolic | G5: Sunstorm Copper | H5: 29
A6: Row 53 | B6: 23026 | C6: 2 | D6: 50 | E6: 196 | F6: Alucobond Plus | G6: Silver Metallic | H6: 4
A7: Row 53 | B7: 23028 | C7: 1 | D7: 62 | E7: 196 | F7: Alucobond Plus | G7: Dusty Charcoal | H7: 27
A8: Row 53 | B8: 23030 | C8: 4 | D8: 62 | E8: 196 | F8: Alucobond Plus | G8: Statuary Bronze | H8: 1
A9: Row 53 | B9: 24010 | C9: 7 | D9: 62 | E9: 196 | F9: Reyobond | G9: Bone White | H9: 28
A10: Row 53 | B10: 24024 | C10: 2 | D10: 62 | E10: 196 | F10: Alucobond Plus | G10: Blue Stone Charcoal Mask | H10: 15
A11: Row 53 | B11: 24024 | C11: 10 | D11: 62 | E11: 196 | F11: Alucobond Plus | G11: Bone White | H11: 17
A12: Row 53 | B12: 24028 | C12: 2 | D12: 62 | E12: 196 | F12: Alucobond Plus | G12: Champagne Metallic Mask | H12: 26
A13: Row 53 | B13: 24028 | C13: 33 | D13: 62 | E13: 196 | F13: Alucobond Plus | G13: Champagne Metallic | H13: 25
... A67: Row 54 | B67: 23030 | C67: 5 | D67: 62 | E67: 196 | F67: Alucobond Plus | G67: Statuary Brozne | H67: 2
A68: Row 54 | B68: 23035 | C68: 2 | F68: Alucobond Plus | G68: Greyhound | H68: 30
A69: Row 54 | B69: 24003 | C69: 3 | D69: 62 | E69: 196 | F69: Alucobond Plus | G69: Union Charcoal | H69: 4
A70: Row 54 | B70: 24007 | C70: 2 | D70: 62 | E70: 196 | F70: Alucobond Plus | G70: Mica Grey | H70: 2
A71: Row 54 | B71: 24010 | C71: 1 | D71: 62 | E71: 196 | F71: Reyobond | G71: Bone White | H71: 28
A72: Row 54 | B72: 24010 | C72: 3 | D72: 62 | E72: 196 | F72: Reyobond | G72: Bone White | H72: 28
A73: Row 54 | B73: 24010 | C73: 2 | D73: 62 | E73: 196 | F73: Alucobond Plus | G73: Bone White | H73: 28
A74: Row 54 | B74: 24015 | C74: 2 | D74: 62 | E74: 196 | F74: Alucobond Plus | G74: Award Blue | H74: 26
A75: Row 54 | B75: 24016 | C75: 11 | D75: 62 | E75: 196 | F75: Alucobond Plus | G75: Anodic Clear | H75: 4
A76: Row 54 | B76: 24019 | C76: 8 | D76: 62 | E76: 196 | F76: Alucobond Plus | G76: Anodic Clear | H76: 6
A77: Row 54 | B77: 24021 | C77: 20 | D77: 62 | E77: 196 | F77: Alucobond Plus | G77: JLR Champagne Metallic | H77: 25
A78: Row 54 | B78: 24021 | C78: 19 | D78: 62 | E78: 196 | F78: Alucobond Plus | G78: JLR Champagne Metallic | H78: 25
A79: Row 54 | B79: 24021 | C79: 13 | D79: 62 | E79: 196 | F79: Alucobond Plus | G79: JLR Champagne Metallic | H79: 25
A80: Row 54 | B80: 24021 | C80: 5 | D80: 62 | E80: 196 | F80: Alucobond Plus | G80: JLR Champagne Metallic | H80: 25
... A165: Row 55 | B165: 25021 | C165: 2 | D165: 62 | E165: 196 | F165: Alucobond Plus | G165: Beach Stone Gray Metallic | H165: 18
A166: Row 55 | B166: 23009 | D166: 62 | E166: 196 | F166: Alucobond Plus | G166: Champagne Metallic | H166: 1
A167: Row 55 | B167: 25021 | C167: 1 | D167: 62 | E167: 196 | F167: Alucobond Plus | G167: Beach Stone Gray Metallic | H167: 25
A168: Row 55 | B168: 24003 | C168: 1 | D168: 62 | E168: 196 | F168: Reyobond | G168: Union Charcoal | H168: 1
A169: Row 56 | B169: 23012 | C169: 56 | D169: 62 | E169: 196 | F169: Alucobond Plus | G169: SLCIA Champagne Bronze Metallic | H169: 5
A170: Row 56 | B170: 24028 | C170: 18 | D170: 62 | E170: 196 | F170: Alucobond Plus | G170: Champagne Metallic Mask | H170: 33
A171: Row 56 | B171: 23012 | C171: 57 | D171: 62 | E171: 196 | F171: Alucobond Plus | G171: SLCIA Champagne Bronze Metallic | H171: 9
A172: Row 56 | B172: 24028 | C172: 22 | D172: 62 | E172: 196 | F172: Alucobond Plus | G172: Champagne Metallic Mask | H172: 44
A173: Row 56 | B173: 24021 | C173: 27 | D173: 62 | E173: 196 | F173: Alucobond Plus | G173: Red Fire | H173: 3
A174: Row 56 | B174: 22005 | C174: 2 | D174: 62 | E174: 196 | F174: Alucobond Plus | G174: Dark Copper Metallic | H174: 7
A175: Row 56 | B175: 24021 | C175: 8 | D175: 62 | E175: 196 | F175: Alucobond Plus | G175: JLR Champagne Metallic | H175: 10
A176: Row 56 | B176: 24021 | C176: 9 | D176: 62 | E176: 196 | F176: Alucobond Plus | G176: JLR Champagne Metallic | H176: 25
A177: Row 56 | B177: 24021 | C177: 21 | D177: 62 | E177: 196 | F177: Alucobond Plus | G177: JLR Champagne Metallic | H177: 25
...

Sheet SPL_inventory
A1: Location_ID | B1: Job_Number | C1: Pallet | D1: Size_W | E1: Size_L | F1: Color | G1: Thickness_mm | H1: Quantity
A2: Tent 1 | B2: 23018 | C2: 3 | D2: 50 | E2: 99 | F2: Vintago - VI 001 | G2: 8 | H2: 10
A3: Tent 1 | B3: 22032 | C3: 7 | D3: 50 | E3: 99 | F3: Nobilis Granite 622 | G3: 8 | H3: 40
A4: Tent 1 | B4: 20003 | C4: 2 | D4: 48 | E4: 96 | F4: REFLEX Dark Silver 9222 | G4: 8 | H4: 6
A5: Tent 1 | B5: 22032 | C5: 22 | D5: 50 | E5: 99 | F5: Nobilis Granite 622 | G5: 8 | H5: 3
A6: Tent 1 | B6: 23029 | C6: 6 | D6: 50 | E6: 99 | F6: Nobilis Granite 622 | G6: 8 | H6: 3
A7: Tent 1 | B7: 22006 | C7: 9 | D7: 48 | E7: 96 | F7: Zenor 69055 | G7: 8 | H7: 1
A8: Tent 1 | B8: 20048 | C8: 43 | D8: 50 | E8: 99 | F8: Carat R-Color: Onyx 7091 | G8: 8 | H8: 40
A9: Tent 1 | B9: 21038 | C9: 28 | D9: 48 | E9: 96 | F9: Nobilis: Jade 522 | G9: 8 | H9: 6
A10: Tent 1 | B10: 21044 | C10: 7 | D10: 50 | E10: 98 | F10: AVERA: AV 020 | G10: 8 | H10: 1
A11: Tent 1 | B11: 21037 | C11: 5 | D11: 50 | E11: 99 | F11: CARAT R-COLOR: Topaz 7070 R | G11: 8 | H11: 7
A12: Tent 1 | B12: 24005 | C12: 2 | D12: 50 | E12: 99 | F12: Reflex: Crystal 4111 | G12: 8 | H12: 3
A13: Tent 1 | B13: 22047 | C13: 6 | D13: 50 | E13: 99 | F13: Nobilis: Natura Gobit 118-22 As1 | G13: 8 | H13: 8
... A17: Tent 1 | B17: 22026 | C17: 4 | D17: 50 | E17: 120 | F17: Nobilis: Jade 522 | G17: 8 | H17: 4
A18: Tent 1 | B18: 20048 | C18: 42 | D18: 50 | E18: 99 | F18: CARAT R-COLOR: Onyx 7091 | G18: 8 | H18: 35 | J18: Note
A19: Tent 3 | B19: 25007 | C19: 1 | D19: 50 | E19: 99 | F19: Planea HR: Sw6594-Ref.Nr. 96-25 | G19: 8 | H19: 40
A20: Tent 3 | B20: 22017 | C20: 9 | D20: 48 | E20: 96 | F20: CARAT: Sahara 7002 | G20: 8 | H20: 4
A21: Tent 3 | C21: ? | F21: Largo Carat | G21: 8 | H21: 2
A22: Tent 3 | B22: 22029 | C22: 9 | D22: 50 | E22: 120 | F22: Nobilis Amber 723 | G22: 8 | H22: 11
A23: Tent 3 | B23: 25007 | C23: 2 | D23: 50 | E23: 99 | F23: Planea HR: Sw6594-Ref.Nr. 96-25 | G23: 8 | H23: 31
A24: Tent 3 | B24: 20048 | C24: 41 | D24: 48 | E24: 96 | F24: CARAT R-COLOR: Onyx 7091 | G24: 8 | H24: 9 | J24: Note
A25: Tent 3 | B25: 20038 | C25: 4 | D25: 50 | E25: 99 | F25: CARAT HR: Sapphire 7060 | G25: 8 | H25: 4
A26: Tent 3 | B26: 23017 | C26: 9 | D26: 49 | E26: 99 | F26: Patina 222 | G26: 8 | H26: 2 | J26: Note
A27: Tent 3 | B27: 22026 | C27: 22 | D27: 50 | E27: 120 | F27: NOBILIS: Jade 522 | G27: 8 | H27: 6
A28: Tent 3 | B28: 24005 | C28: 7 | D28: 50 | E28: 99 | F28: Reflex: Crystal 4111 | G28: 8 | H28: 2 | J28: Note
A29: Tent 3 | B29: 25401 | C29: 1 | D29: 50 | E29: 120 | F29: Carat Ivory 8099 | G29: 8 | H29: 2
A30: Tent 3 | B30: 24005 | C30: 4 | D30: 50 | E30: 120 | F30: Nobilis: Crystal 124 | G30: 8 | H30: 1
A31: Tent 3 | B31: 23015 | C31: 24 | D31: 49 | E31: 120 | F31: Patina Original 222 | G31: 8 | H31: 5
A32: Tent 3 | B32: 23033 | C32: 44 | D32: 50 | E32: 120 | F32: Patina Original P545 | G32: 8 | H32: 11
A33: Tent 3 | B33: 22034 | C33: 16 | D33: 50 | E33: 120 | F33: LARGO: Gravial Anthracite 3020 | G33: 8 | H33: 4
A34: Tent 3 | B34: 23019 | C34: 9 | D34: 50 | E34: 120 | F34: CARAT: Onyx 7091 | G34: 8 | H34: 16
A35: Tent 3 | B35: 22002 | C35: 6 | D35: 48 | E35: 120 | F35: CARAT F-COLOR: Sahara 7001 | G35: 8 | H35: 9
A36: Tent 3 | B36: 23031 | C36: 8 | D36: 50 | E36: 120 | F36: Patina Original P070 NXT | G36: 8 | H36: 15
A37: Tent 6 | B37: 22017 | C37: 6 | D37: 48 | E37: 120 | F37: CARAT: Sahara 7002 | G37: 8 | H37: 1
A38: Tent 6 | B38: 23407 | C38: 1 | D38: 48 | E38: 120 | F38: CARAT HR: Onyx 7099 | G38: 8 | H38: 1
A39: Tent 6 | B39: 22030 | C39: 9 | D39: 48 | E39: 120 | F39: LARGO: Planea Solarit P3 5981 | G39: 8 | H39: 3
A40: Tent 6 | B40: 20048 | C40: 97 | D40: 50 | E40: 120 | F40: CARAT HR: Sapphire 7060 | G40: 8 | H40: 1
... A46: Tent 6 | B46: 22037 | C46: 2 | D46: 48 | E46: 120 | F46: Nobilis: Crystal 124 | G46: 8 | H46: 16
A47: Tent 6 | B47: 22048 | C47: 95 | D47: 50 | E47: 120 | F47: Carat sapphire 7060 | G47: 8 | H47: 12 | J47: Note
A48: Tent 6 | B48: 22047 | C48: 1 | D48: 50 | E48: 120 | F48: Nobilis: Natura Gobit 381438 | G48: 8 | H48: 4 | J48: Notes
...

Sheet HPL_Inventory
A1: Location_ID | B1: Job_Number | C1: Pallet | D1: Size_W | E1: Size_L | F1: Color | G1: Thickness_mm | H1: Quantity
A2: Shop | B2: 25014 | C2: 1 | D2: 73 | E2: 110 | F2: German Blue 0237 | G2: 10 | H2: 18
A3: Shop | B3: 25014 | C3: 3 | D3: 73 | E3: 161 | F3: German Blue 0237 | G3: 10 | H3: 9
A4: Shop | B4: 25014 | C4: 9 | D4: 73 | E4: 161 | F4: Enigma 0923 | G4: 10 | H4: 4
A5: Shop | B5: 25014 | C5: 10 | D5: 73 | E5: 161 | F5: Enigma 0923 | G5: 10 | H5: 13
A6: Shop | B6: 25014 | C6: 11 | D6: 73 | E6: 161 | F6: Enigma 0923 | G6: 10 | H6: 6
A7: Shop | B7: 25014 | C7: 12 | D7: 73 | E7: 161 | F7: Enigma 0923 | G7: 10 | H7: 13
A8: Shop | B8: 25014 | C8: 6 | D8: 73 | E8: 161 | F8: Enigma 0923 | G8: 10 | H8: 9
A9: Shop | B9: 25014 | C9: 7 | D9: 73 | E9: 161 | F9: Enigma 0923 | G9: 10 | H9: 13
A10: Shop | B10: 25014 | C10: 8 | D10: 73 | E10: 161 | F10: Enigma 0923 | G10: 10 | H10: 13
A11: Shop | B11: 25014 | C11: 2 | D11: 73 | E11: 161 | F11: German Blue 0237 | G11: 10 | H11: 13
A12: Shop | B12: 25014 | C12: 5 | D12: 73 | E12: 161 | F12: German Blue 0237 | G12: 10 | H12: 13
A13: Shop | B13: 24017 | C13: 35 | D13: 50 | E13: 100 | F13: Nobilis Gobit N 38 5438 | G13: 8 | H13: 27
... A21: Shop | B21: 24031 | C21: 1 | D21: 50 | E21: 120 | F21: Enigma 0923 | G21: 10 | H21: 13

Sheet Rivet_Inventory
A1: Location_ID | B1: Job_Number | C1: Color | D1: Quantity
A2: Rivet Room | C2: Silver Polish | D2: 4500
A3: Rivet Room | C3: White Shore | D3: 5000
A4: Rivet Room | B4: 22050 | C4: Creative Bronze | D4: 5000
A5: Rivet Room | B5: 23015 | C5: Anodic Clear Mica | D5: 500
A6: Rivet Room | C6: Bright Green | D6: 1000
A7: Rivet Room | B7: 23023 | C7: Slate Gray | D7: 2000
A8: Rivet Room | B8: 25004 | C8: Silver Polish | D8: 1500
A9: Rivet Room | B9: 23015 | C9: Satin Mica | D9: 4000
A10: Rivet Room | B10: 23012 | C10: Champagne Metalic Df-020 | D10: 3500
A11: Rivet Room | C11: Light Copper | D11: 2500
A12: Rivet Room | B12: 23012 | C12: Champagne Metalic Df-020 | D12: 8000
A13: Rivet Room | B13: 23023 | C13: Silver Polish | D13: 250
A14: Rivet Room | C14: Light Copper | D14: 500
A15: Rivet Room | B15: 24021 | C15: Champagne Metalic Df-036 | D15: 3500
A16: Rivet Room | B16: 23008 | C16: Anodic Clear Mica | D16: 4500
A17: Rivet Room | B17: 22038 | C17: Sage Green Df-027 | D17: 500
A18: Rivet Room | B18: 21033 | C18: Impressive Pewter | D18: 2500
A19: Rivet Room | B19: 23023 | C19: Sunstorm Copper | D19: 4500
A20: Rivet Room | B20: 22003 | C20: Red Spice | D20: 4000
A21: Rivet Room | B21: 25002 | C21: Champagne Metalic | D21: 1000
A22: Rivet Room | C22: Sage Green Df-027 | D22: 1000
A23: Rivet Room | C23: Seasonal Mustard | D23: 1500
A24: Rivet Room | B24: 22003 | C24: Candle Light | D24: 2000
A25: Rivet Room | B25: 24021 | C25: Champagne Metalic Df-036 | D25: 5000
A26: Rivet Room | B26: 22003 | C26: Lupine Blue | D26: 1500
A27: Rivet Room | B27: 23028 | C27: Creative Bronze | D27: 1500
A28: Rivet Room | B28: 25006 | C28: Black | D28: 5000
A29: Rivet Room | B29: 23012 | C29: Light Copper Met | D29: 5000
A30: Rivet Room | B30: 23030 | C30: Creek Medium Bronze | D30: 5000
A31: Rivet Room | C31: White Shore | D31: 3500
A32: Rivet Room | B32: 24027 | C32: Anadized Clear | D32: 5000
A33: Rivet Room | B33: 23016 | C33: Sapphire Blue | D33: 3000
A34: Rivet Room | B34: 21033 | C34: Impressive Pewter | D34: 3500
A35: Rivet Room | B35: 23012 | C35: Light Copper | D35: 4500
A36: Rivet Room | B36: 24027 | C36: Copper Penny | D36: 4500
A37: Rivet Room | C37: Silver Polish | D37: 4500
A38: Rivet Room | B38: 24021 | C38: Patriot Red | D38: 2500
A39: Rivet Room | B39: 23012 | C39: Copper Penny | D39: 2500
A40: Rivet Room | B40: 23015 | C40: Satin Mica | D40: 2500
...

Sheet Misc_Inventory
A1: Category | B1: Name | C1: Size | D1: Color | E1: Quantity | F1: Unit
A2: Misc | B2: Staples | C2: 1.75 | E2: 5 | F2: boxes
A3: Misc | B3: Staples | C3: 1.25 | E3: 4 | F3: boxes
A4: Misc | B4: Staples | C4: 1 | F4: each
A5: Misc | B5: Framing Nails | E5: 5.5 | F5: boxes
A6: Misc | B6: Paint | D6: Blue | F6: each
A7: Misc | B7: Paint | D7: Orange | F7: each
A8: Misc | B8: Paint | D8: Black | F8: each
A9: Misc | B9: Paint | D9: White | F9: each
A10: Misc | B10: Paint | D10: Red | F10: each
A11: Misc | B11: Paint | D11: Purple | F11: each
A12: Misc | B12: Paint | D12: Green | F12: each
A13: Misc | B13: Wrap | C13: 6' | E13: 7.5 | F13: each
A14: Misc | B14: Wrap | C14: 8' | E14: 2.5 | F14: each
A15: Misc | B15: 2X4 | E15: 11 | F15: each
A16: Misc | B16: 1X8 | E16: 10 | F16: each
A17: Misc | B17: Cardboard | E17: 1 | F17: each
A18: Misc | B18: Masonite | E18: 3 | F18: each
A19: Misc | B19: 3/4 Foam Sht | E19: 1 | F19: each
A20: Misc | B20: Monkey Fur | D20: Black | F20: each
A21: Misc | B21: Monkey Fur | D21: Silver | E21: 25 | F21: boxes
A22: Misc | B22: Dry Gusset | E22: 24000 | F22: &1/2crate
A23: Misc | B23: C4 Gusset | E23: 1 | F23: crate
A24: Misc | B24: Dry Clip | E24: 5100 | F24: each
A25: Misc | B25: Edge Binder | D25: Black | E25: 45 | F25: boxes
A26: Misc | B26: Sp Niet 4X18/K15 | E26: 17000 | F26: each
A27: Misc | B27: Tw-S-D13 5,5X29 | E27: 3250 | F27: each
A28: Misc | B28: Tu-S-6X13-A4 | E28: 500 | F28: each
A29: Misc | B29: Tw-S-D13 5,5X38 | E29: 4500 | F29: each
A30: Misc | B30: Tuf-S-6X12-A4 | E30: 2500 | F30: each
A31: Misc | B31: 795 Black | E31: 2 | F31: boxes
A32: Misc | B32: 791 Gray | E32: 2 | F32: boxes
A33: Misc | B33: Plastic Wrap | E33: 10 | F33: each
A34: Misc | B34: Flashing Tape | E34: 48 | F34: each
A35: Misc | B35: Tu-S-6X11-A4 | E35: 17 | F35: boxes
A36: Misc | B36: Tw-S-D13 5,5 38 | E36: 17 | F36: boxes
A37: Misc | B37: Tuf-S-6X12-A4 | E37: 1000 | F37: each
